<?xml version="1.0" encoding="utf-8"?>
<!-- This URDF was automatically created by SolidWorks to URDF Exporter! Originally created by Stephen Brawner (brawner@gmail.com) 
     Commit Version: 1.6.0-4-g7f85cfe  Build Version: 1.6.7995.38578
     For more information, please see http://wiki.ros.org/sw_urdf_exporter -->
<robot
  name="line_follower_robot">
  <link
    name="base_link">
    <inertial>
      <origin
        xyz="0.010085 -7.8763E-06 -0.0066048"
        rpy="0 0 0" />
      <mass
        value="0.12859" />
      <inertia
        ixx="5.2146E-05"
        ixy="-1.0769E-19"
        ixz="2.9025E-20"
        iyy="0.00017957"
        iyz="1.8099E-14"
        izz="0.00022799" />
    </inertial>
    <visual>
      <origin
        xyz="0 0 0"
        rpy="0 0 0" />
      <geometry>
        <mesh
          filename="package://line_follower_robot/meshes/base_link.STL" />
      </geometry>
      <material
        name="">
        <color
          rgba="1 1 1 0.3" />
      </material>
    </visual>
    <collision>
      <origin
        xyz="0 0 0"
        rpy="0 0 0" />
      <geometry>
        <mesh
          filename="package://line_follower_robot/meshes/base_link.STL" />
      </geometry>
    </collision>
  </link>
  <link
    name="left_wheel">
    <inertial>
      <origin
        xyz="2.2714E-09 -3.2445E-08 -0.0073729"
        rpy="0 0 0" />
      <mass
        value="0.021404" />
      <inertia
        ixx="8.6283E-06"
        ixy="-3.3802E-12"
        ixz="3.1432E-13"
        iyy="8.6269E-06"
        iyz="-9.8955E-12"
        izz="1.4515E-05" />
    </inertial>
    <visual>
      <origin
        xyz="0 0 0"
        rpy="0 0 0" />
      <geometry>
        <mesh
          filename="package://line_follower_robot/meshes/left_wheel.STL" />
      </geometry>
      <material
        name="">
        <color
          rgba="0.79216 0.81961 0.93333 1" />
      </material>
    </visual>
    <collision>
      <origin
        xyz="0 0 0"
        rpy="0 0 0" />
      <geometry>
        <mesh
          filename="package://line_follower_robot/meshes/left_wheel.STL" />
      </geometry>
    </collision>
  </link>
  <joint
    name="left_wheel_joint"
    type="continuous">
    <origin
      xyz="-0.033259 0.07575 -0.01375"
      rpy="-1.5708 0 0" />
    <parent
      link="base_link" />
    <child
      link="left_wheel" />
    <axis
      xyz="0 0 1" />
  </joint>
  <link
    name="right_wheel">
    <inertial>
      <origin
        xyz="2.2714E-09 3.2445E-08 0.0073729"
        rpy="0 0 0" />
      <mass
        value="0.021404" />
      <inertia
        ixx="8.6283E-06"
        ixy="3.3802E-12"
        ixz="-3.1432E-13"
        iyy="8.6269E-06"
        iyz="-9.8955E-12"
        izz="1.4515E-05" />
    </inertial>
    <visual>
      <origin
        xyz="0 0 0"
        rpy="0 0 0" />
      <geometry>
        <mesh
          filename="package://line_follower_robot/meshes/right_wheel.STL" />
      </geometry>
      <material
        name="">
        <color
          rgba="0.79216 0.81961 0.93333 1" />
      </material>
    </visual>
    <collision>
      <origin
        xyz="0 0 0"
        rpy="0 0 0" />
      <geometry>
        <mesh
          filename="package://line_follower_robot/meshes/right_wheel.STL" />
      </geometry>
    </collision>
  </link>
  <joint
    name="right_wheel_joint"
    type="continuous">
    <origin
      xyz="-0.033259 -0.07575 -0.01375"
      rpy="-1.5708 0 0" />
    <parent
      link="base_link" />
    <child
      link="right_wheel" />
    <axis
      xyz="0 0 1" />
  </joint>
  <link
    name="castor_base_link">
    <inertial>
      <origin
        xyz="0.0076868 0.00024426 -0.013506"
        rpy="0 0 0" />
      <mass
        value="0.013786" />
      <inertia
        ixx="1.2468E-06"
        ixy="-9.7727E-10"
        ixz="2.4805E-07"
        iyy="1.3131E-06"
        iyz="2.4557E-09"
        izz="1.6977E-06" />
    </inertial>
    <visual>
      <origin
        xyz="0 0 0"
        rpy="0 0 0" />
      <geometry>
        <mesh
          filename="package://line_follower_robot/meshes/castor_base_link.STL" />
      </geometry>
      <material
        name="">
        <color
          rgba="0.63922 0.66667 0.67843 1" />
      </material>
    </visual>
    <collision>
      <origin
        xyz="0 0 0"
        rpy="0 0 0" />
      <geometry>
        <mesh
          filename="package://line_follower_robot/meshes/castor_base_link.STL" />
      </geometry>
    </collision>
  </link>
  <joint
    name="castor_joint"
    type="continuous">
    <origin
      xyz="0.072581 0 -0.0025"
      rpy="0 0 0" />
    <parent
      link="base_link" />
    <child
      link="castor_base_link" />
    <axis
      xyz="0 0 1" />
  </joint>
  <link
    name="castor_wheel">
    <inertial>
      <origin
        xyz="2.6204E-11 6.9389E-18 -2.7771E-09"
        rpy="0 0 0" />
      <mass
        value="0.0082874" />
      <inertia
        ixx="6.393E-07"
        ixy="7.7035E-23"
        ixz="-3.5083E-09"
        iyy="6.3927E-07"
        iyz="1.1499E-22"
        izz="1.0111E-06" />
    </inertial>
    <visual>
      <origin
        xyz="0 0 0"
        rpy="0 0 0" />
      <geometry>
        <mesh
          filename="package://line_follower_robot/meshes/castor_wheel.STL" />
      </geometry>
      <material
        name="">
        <color
          rgba="1 1 1 1" />
      </material>
    </visual>
    <collision>
      <origin
        xyz="0 0 0"
        rpy="0 0 0" />
      <geometry>
        <mesh
          filename="package://line_follower_robot/meshes/castor_wheel.STL" />
      </geometry>
    </collision>
  </link>
  <joint
    name="castor_wheel_joint"
    type="continuous">
    <origin
      xyz="0.015014 0.00014167 -0.02296"
      rpy="-1.5708 0 0" />
    <parent
      link="castor_base_link" />
    <child
      link="castor_wheel" />
    <axis
      xyz="0 0 1" />
  </joint>
</robot>