<sdf version='1.7'>
  <model name='line_follower_robot'>
    <joint name='world_joint' type='fixed'>
      <pose relative_to='__model__'>0 0 1 0 -0 0</pose>
      <parent>world</parent>
      <child>base_link</child>
    </joint>
    <link name='base_link'>
      <pose relative_to='world_joint'>0 0 0 0 -0 0</pose>
      <inertial>
        <pose>0.010085 -8e-06 -0.006605 0 -0 0</pose>
        <mass>0.12859</mass>
        <inertia>
          <ixx>5.2146e-05</ixx>
          <ixy>0</ixy>
          <ixz>0</ixz>
          <iyy>0.00017957</iyy>
          <iyz>0</iyz>
          <izz>0.00022799</izz>
        </inertia>
      </inertial>
      <collision name='base_link_collision'>
        <pose>0 0 0 0 -0 0</pose>
        <geometry>
          <mesh>
            <scale>1 1 1</scale>
            <uri>model://line_follower_robot/meshes/base_link.STL</uri>
          </mesh>
        </geometry>
      </collision>
      <visual name='base_link_visual'>
        <pose>0 0 0 0 -0 0</pose>
        <geometry>
          <mesh>
            <scale>1 1 1</scale>
            <uri>model://line_follower_robot/meshes/base_link.STL</uri>
          </mesh>
        </geometry>
      </visual>
    </link>
    <joint name='castor_joint' type='revolute'>
      <pose relative_to='base_link'>0.072581 0 -0.0025 0 -0 0</pose>
      <parent>base_link</parent>
      <child>castor_base_link</child>
      <axis>
        <xyz>0 0 1</xyz>
        <limit>
          <lower>-1e+16</lower>
          <upper>1e+16</upper>
        </limit>
        <dynamics>
          <spring_reference>0</spring_reference>
          <spring_stiffness>0</spring_stiffness>
        </dynamics>
      </axis>
    </joint>
    <link name='castor_base_link'>
      <pose relative_to='castor_joint'>0 0 0 0 -0 0</pose>
      <inertial>
        <pose>0 0 0 0 -0 0</pose>
        <mass>0.01</mass>
        <inertia>
          <ixx>1e-05</ixx>
          <ixy>0</ixy>
          <ixz>0</ixz>
          <iyy>1e-05</iyy>
          <iyz>0</iyz>
          <izz>1e-05</izz>
        </inertia>
      </inertial>
      <collision name='castor_base_link_collision'>
        <pose>0 0 0 0 -0 0</pose>
        <geometry>
          <mesh>
            <scale>1 1 1</scale>
            <uri>model://line_follower_robot/meshes/castor_wheel.STL</uri>
          </mesh>
        </geometry>
      </collision>
      <visual name='castor_base_link_visual'>
        <pose>0 0 0 0 -0 0</pose>
        <geometry>
          <mesh>
            <scale>1 1 1</scale>
            <uri>model://line_follower_robot/meshes/castor_base_link.STL</uri>
          </mesh>
        </geometry>
      </visual>
    </link>
    <joint name='castor_wheel_joint' type='revolute'>
      <pose relative_to='castor_base_link'>0.015014 0.000142 -0.02296 -1.5708 0 0</pose>
      <parent>castor_base_link</parent>
      <child>castor_wheel</child>
      <axis>
        <xyz>0 0 1</xyz>
        <limit>
          <lower>-1e+16</lower>
          <upper>1e+16</upper>
        </limit>
        <dynamics>
          <spring_reference>0</spring_reference>
          <spring_stiffness>0</spring_stiffness>
        </dynamics>
      </axis>
    </joint>
    <link name='castor_wheel'>
      <pose relative_to='castor_wheel_joint'>0 0 0 0 -0 0</pose>
      <inertial>
        <pose>0 0 0 0 -0 0</pose>
        <mass>0.01</mass>
        <inertia>
          <ixx>1e-05</ixx>
          <ixy>0</ixy>
          <ixz>0</ixz>
          <iyy>1e-05</iyy>
          <iyz>0</iyz>
          <izz>1e-05</izz>
        </inertia>
      </inertial>
      <collision name='castor_wheel_collision'>
        <pose>0 0 0 0 -0 0</pose>
        <geometry>
          <mesh>
            <scale>1 1 1</scale>
            <uri>model://line_follower_robot/meshes/castor_wheel.STL</uri>
          </mesh>
        </geometry>
      </collision>
      <visual name='castor_wheel_visual'>
        <pose>0 0 0 0 -0 0</pose>
        <geometry>
          <mesh>
            <scale>1 1 1</scale>
            <uri>model://line_follower_robot/meshes/castor_wheel.STL</uri>
          </mesh>
        </geometry>
      </visual>
    </link>
    <joint name='left_wheel_joint' type='revolute'>
      <pose relative_to='base_link'>-0.033259 0.07575 -0.01375 -1.5708 0 0</pose>
      <parent>base_link</parent>
      <child>left_wheel</child>
      <axis>
        <xyz>0 0 1</xyz>
        <limit>
          <lower>-1e+16</lower>
          <upper>1e+16</upper>
        </limit>
        <dynamics>
          <spring_reference>0</spring_reference>
          <spring_stiffness>0</spring_stiffness>
        </dynamics>
      </axis>
    </joint>
    <link name='left_wheel'>
      <pose relative_to='left_wheel_joint'>0 0 0 0 -0 0</pose>
      <inertial>
        <pose>0 0 -0.007373 0 -0 0</pose>
        <mass>0.021404</mass>
        <inertia>
          <ixx>8.6283e-06</ixx>
          <ixy>0</ixy>
          <ixz>0</ixz>
          <iyy>8.6269e-06</iyy>
          <iyz>0</iyz>
          <izz>1.4515e-05</izz>
        </inertia>
      </inertial>
      <collision name='left_wheel_collision'>
        <pose>0 0 0 0 -0 0</pose>
        <geometry>
          <mesh>
            <scale>1 1 1</scale>
            <uri>model://line_follower_robot/meshes/left_wheel.STL</uri>
          </mesh>
        </geometry>
      </collision>
      <visual name='left_wheel_visual'>
        <pose>0 0 0 0 -0 0</pose>
        <geometry>
          <mesh>
            <scale>1 1 1</scale>
            <uri>model://line_follower_robot/meshes/left_wheel.STL</uri>
          </mesh>
        </geometry>
      </visual>
    </link>
    <joint name='right_wheel_joint' type='revolute'>
      <pose relative_to='base_link'>-0.033259 -0.07575 -0.01375 -1.5708 0 0</pose>
      <parent>base_link</parent>
      <child>right_wheel</child>
      <axis>
        <xyz>0 0 1</xyz>
        <limit>
          <lower>-1e+16</lower>
          <upper>1e+16</upper>
        </limit>
        <dynamics>
          <spring_reference>0</spring_reference>
          <spring_stiffness>0</spring_stiffness>
        </dynamics>
      </axis>
    </joint>
    <link name='right_wheel'>
      <pose relative_to='right_wheel_joint'>0 0 0 0 -0 0</pose>
      <inertial>
        <pose>0 0 0.007373 0 -0 0</pose>
        <mass>0.021404</mass>
        <inertia>
          <ixx>8.6283e-06</ixx>
          <ixy>0</ixy>
          <ixz>0</ixz>
          <iyy>8.6269e-06</iyy>
          <iyz>0</iyz>
          <izz>1.4515e-05</izz>
        </inertia>
      </inertial>
      <collision name='right_wheel_collision'>
        <pose>0 0 0 0 -0 0</pose>
        <geometry>
          <mesh>
            <scale>1 1 1</scale>
            <uri>model://line_follower_robot/meshes/right_wheel.STL</uri>
          </mesh>
        </geometry>
      </collision>
      <visual name='right_wheel_visual'>
        <pose>0 0 0 0 -0 0</pose>
        <geometry>
          <mesh>
            <scale>1 1 1</scale>
            <uri>model://line_follower_robot/meshes/right_wheel.STL</uri>
          </mesh>
        </geometry>
      </visual>
    </link>
  </model>
</sdf>
